Workbook

Sheet PL 300726
A1: ITEM ID | B1: PART | C1: CTO | D1: SC | E1: FUNCTIONAL_PART | F1: DESCRIPTION | G1: DETECTOR_ROLE | H1: SUPPLIER NOTES | I1: CLOSING NOTES | J1: STATUS ELECNOR | K1: STATUS IUP | L1: CLOSING DATE ENEL | M1: CLOSING DATE - ELECNOR | N1: CIRCUITO | O1: ESTADO | P1: DETALLE ESTADO | Q1: EXTERNO
A2: PHL-39058 | B2: Cables | C2: CAJAS | D2: CAJAS | E2: Caja de empalme continua a la ITS24 | F2: Sellado ductos material impermeabilizante | G2: Electrical Specialist | H2: Pendiente validacion de enel | J2: CL | K2: CERRADO | L2: 46303 | N2: =IF(ISNUMBER(PL[[#This Row],[CTO]]),"CTO "&PL[[#This Row],[CTO]],"Otros") -> Otros | O2: =IF(PL[[#This Row],[STATUS IUP]]="CERRADO","CERRADO",IF(ISNUMBER(SEARCH("validacion de enel",PL[[#This Row],[SUPPLIER NOTES]])),"PTE Validar Enel","ABIERTO")) -> CERRADO | P2: =IF(PL[[#This Row],[ESTADO]]="CERRADO","Cerrados IUP",IF(PL[[#This Row],[ESTADO]]="PTE Validar Enel","Pendiente cierre ENEL",IF(ISNUMBER(SEARCH("suministro",PL[[#This Row],[SUPPLIER NOTES]])),"Suministros",IF(PL[[#This Row],[SC]]="SOCIAL","Social",IF(ISNUMBER(SEARCH("monolito",PL[[#This Row],[DESCRIPTION]])),"Monolitos","Varios"))))) -> Cerrados IUP | Q2: =IF(ISNA(MATCH(PL[[#This Row],[ITEM ID]],Externos!$A:$A,0)),"",IF(PL[[#This Row],[DETECTOR_ROLE]]="Sustainability Manager","SOCIAL",IF(INDEX(Externos!$D:$D,MATCH(PL[[#This Row],[ITEM ID]],Externos!$A:$A,0))="TRINA",IF(PL[[#This Row],[DETECTOR_ROLE]]="O&M","Trina O&M",IF(PL[[#This Row],[DETECTOR_ROLE]]="Commissioning Manager","Trina Commissioning","Trina Electric")),"O&M")))
A3: PHL-39065 | B3: Cables | C3: CAJAS | D3: CAJAS | E3: Caja de empalme continua a la ITS24 | F3: Retoque de pintura en tapas metalicas | G3: Civil Specialist | H3: Pendiente validacion de enel | J3: OP | K3: ABIERTO | N3: =IF(ISNUMBER(PL[[#This Row],[CTO]]),"CTO "&PL[[#This Row],[CTO]],"Otros") -> Otros | O3: =IF(PL[[#This Row],[STATUS IUP]]="CERRADO","CERRADO",IF(ISNUMBER(SEARCH("validacion de enel",PL[[#This Row],[SUPPLIER NOTES]])),"PTE Validar Enel","ABIERTO")) -> PTE Validar Enel | P3: =IF(PL[[#This Row],[ESTADO]]="CERRADO","Cerrados IUP",IF(PL[[#This Row],[ESTADO]]="PTE Validar Enel","Pendiente cierre ENEL",IF(ISNUMBER(SEARCH("suministro",PL[[#This Row],[SUPPLIER NOTES]])),"Suministros",IF(PL[[#This Row],[SC]]="SOCIAL","Social",IF(ISNUMBER(SEARCH("monolito",PL[[#This Row],[DESCRIPTION]])),"Monolitos","Varios"))))) -> Pendiente cierre ENEL | Q3: =IF(ISNA(MATCH(PL[[#This Row],[ITEM ID]],Externos!$A:$A,0)),"",IF(PL[[#This Row],[DETECTOR_ROLE]]="Sustainability Manager","SOCIAL",IF(INDEX(Externos!$D:$D,MATCH(PL[[#This Row],[ITEM ID]],Externos!$A:$A,0))="TRINA",IF(PL[[#This Row],[DETECTOR_ROLE]]="O&M","Trina O&M",IF(PL[[#This Row],[DETECTOR_ROLE]]="Commissioning Manager","Trina Commissioning","Trina Electric")),"O&M")))
A4: PHL-39082 | B4: Cables | C4: CAJAS | D4: CAJAS | E4: caja de paso de la OC5 costado Sur de los CTOS 8-9-10 : | F4: Sellado ductos material impermeabilizante | G4: Electrical Specialist | H4: Pendiente validacion de enel | J4: CL | K4: CERRADO | L4: 46303 | N4: =IF(ISNUMBER(PL[[#This Row],[CTO]]),"CTO "&PL[[#This Row],[CTO]],"Otros") -> Otros | O4: =IF(PL[[#This Row],[STATUS IUP]]="CERRADO","CERRADO",IF(ISNUMBER(SEARCH("validacion de enel",PL[[#This Row],[SUPPLIER NOTES]])),"PTE Validar Enel","ABIERTO")) -> CERRADO | P4: =IF(PL[[#This Row],[ESTADO]]="CERRADO","Cerrados IUP",IF(PL[[#This Row],[ESTADO]]="PTE Validar Enel","Pendiente cierre ENEL",IF(ISNUMBER(SEARCH("suministro",PL[[#This Row],[SUPPLIER NOTES]])),"Suministros",IF(PL[[#This Row],[SC]]="SOCIAL","Social",IF(ISNUMBER(SEARCH("monolito",PL[[#This Row],[DESCRIPTION]])),"Monolitos","Varios"))))) -> Cerrados IUP | Q4: =IF(ISNA(MATCH(PL[[#This Row],[ITEM ID]],Externos!$A:$A,0)),"",IF(PL[[#This Row],[DETECTOR_ROLE]]="Sustainability Manager","SOCIAL",IF(INDEX(Externos!$D:$D,MATCH(PL[[#This Row],[ITEM ID]],Externos!$A:$A,0))="TRINA",IF(PL[[#This Row],[DETECTOR_ROLE]]="O&M","Trina O&M",IF(PL[[#This Row],[DETECTOR_ROLE]]="Commissioning Manager","Trina Commissioning","Trina Electric")),"O&M")))
A5: PHL-39090 | B5: Cables | C5: CAJAS | D5: CAJAS | E5: Caja de paso del costado norte de la OC5 de los CTOS 8-9-10 | F5: Sellado ductos material impermeabilizante | G5: Electrical Specialist | H5: Pendiente validacion de enel | J5: CL | K5: CERRADO | L5: 46303 | N5: =IF(ISNUMBER(PL[[#This Row],[CTO]]),"CTO "&PL[[#This Row],[CTO]],"Otros") -> Otros | O5: =IF(PL[[#This Row],[STATUS IUP]]="CERRADO","CERRADO",IF(ISNUMBER(SEARCH("validacion de enel",PL[[#This Row],[SUPPLIER NOTES]])),"PTE Validar Enel","ABIERTO")) -> CERRADO | P5: =IF(PL[[#This Row],[ESTADO]]="CERRADO","Cerrados IUP",IF(PL[[#This Row],[ESTADO]]="PTE Validar Enel","Pendiente cierre ENEL",IF(ISNUMBER(SEARCH("suministro",PL[[#This Row],[SUPPLIER NOTES]])),"Suministros",IF(PL[[#This Row],[SC]]="SOCIAL","Social",IF(ISNUMBER(SEARCH("monolito",PL[[#This Row],[DESCRIPTION]])),"Monolitos","Varios"))))) -> Cerrados IUP | Q5: =IF(ISNA(MATCH(PL[[#This Row],[ITEM ID]],Externos!$A:$A,0)),"",IF(PL[[#This Row],[DETECTOR_ROLE]]="Sustainability Manager","SOCIAL",IF(INDEX(Externos!$D:$D,MATCH(PL[[#This Row],[ITEM ID]],Externos!$A:$A,0))="TRINA",IF(PL[[#This Row],[DETECTOR_ROLE]]="O&M","Trina O&M",IF(PL[[#This Row],[DETECTOR_ROLE]]="Commissioning Manager","Trina Commissioning","Trina Electric")),"O&M")))
A6: PHL-39096 | B6: Cables | C6: CAJAS | D6: CAJAS | E6: Caja de paso del costado norte de la OC5 de los CTOS 8-9-16 | F6: Retoque de pintura en tapas metalicas | G6: Civil Specialist | H6: Pendiente validacion de enel | J6: OP | K6: ABIERTO | N6: =IF(ISNUMBER(PL[[#This Row],[CTO]]),"CTO "&PL[[#This Row],[CTO]],"Otros") -> Otros | O6: =IF(PL[[#This Row],[STATUS IUP]]="CERRADO","CERRADO",IF(ISNUMBER(SEARCH("validacion de enel",PL[[#This Row],[SUPPLIER NOTES]])),"PTE Validar Enel","ABIERTO")) -> PTE Validar Enel | P6: =IF(PL[[#This Row],[ESTADO]]="CERRADO","Cerrados IUP",IF(PL[[#This Row],[ESTADO]]="PTE Validar Enel","Pendiente cierre ENEL",IF(ISNUMBER(SEARCH("suministro",PL[[#This Row],[SUPPLIER NOTES]])),"Suministros",IF(PL[[#This Row],[SC]]="SOCIAL","Social",IF(ISNUMBER(SEARCH("monolito",PL[[#This Row],[DESCRIPTION]])),"Monolitos","Varios"))))) -> Pendiente cierre ENEL | Q6: =IF(ISNA(MATCH(PL[[#This Row],[ITEM ID]],Externos!$A:$A,0)),"",IF(PL[[#This Row],[DETECTOR_ROLE]]="Sustainability Manager","SOCIAL",IF(INDEX(Externos!$D:$D,MATCH(PL[[#This Row],[ITEM ID]],Externos!$A:$A,0))="TRINA",IF(PL[[#This Row],[DETECTOR_ROLE]]="O&M","Trina O&M",IF(PL[[#This Row],[DETECTOR_ROLE]]="Commissioning Manager","Trina Commissioning","Trina Electric")),"O&M")))
A7: PHL-39103 | B7: Cables | C7: CAJAS | D7: CAJAS | E7: Caja de Empalme Sectioning Pit Cto 09 Lewis 6-13 | F7: Retoque de pintura en tapas metalicas | G7: Civil Specialist | H7: Pendiente validacion de enel | J7: OP | K7: ABIERTO | N7: =IF(ISNUMBER(PL[[#This Row],[CTO]]),"CTO "&PL[[#This Row],[CTO]],"Otros") -> Otros | O7: =IF(PL[[#This Row],[STATUS IUP]]="CERRADO","CERRADO",IF(ISNUMBER(SEARCH("validacion de enel",PL[[#This Row],[SUPPLIER NOTES]])),"PTE Validar Enel","ABIERTO")) -> PTE Validar Enel | P7: =IF(PL[[#This Row],[ESTADO]]="CERRADO","Cerrados IUP",IF(PL[[#This Row],[ESTADO]]="PTE Validar Enel","Pendiente cierre ENEL",IF(ISNUMBER(SEARCH("suministro",PL[[#This Row],[SUPPLIER NOTES]])),"Suministros",IF(PL[[#This Row],[SC]]="SOCIAL","Social",IF(ISNUMBER(SEARCH("monolito",PL[[#This Row],[DESCRIPTION]])),"Monolitos","Varios"))))) -> Pendiente cierre ENEL | Q7: =IF(ISNA(MATCH(PL[[#This Row],[ITEM ID]],Externos!$A:$A,0)),"",IF(PL[[#This Row],[DETECTOR_ROLE]]="Sustainability Manager","SOCIAL",IF(INDEX(Externos!$D:$D,MATCH(PL[[#This Row],[ITEM ID]],Externos!$A:$A,0))="TRINA",IF(PL[[#This Row],[DETECTOR_ROLE]]="O&M","Trina O&M",IF(PL[[#This Row],[DETECTOR_ROLE]]="Commissioning Manager","Trina Commissioning","Trina Electric")),"O&M")))
A8: PHL-38984 | B8: Cables | C8: CAJAS | D8: CAJAS | E8: Caja de Empalme Sectioning Pit Cto 09 Suc 20 | F8: Instalacion de tag y señalizacion RETIE | G8: Project HSE&Q support | J8: CL | K8: CERRADO | M8: 46137 | N8: =IF(ISNUMBER(PL[[#This Row],[CTO]]),"CTO "&PL[[#This Row],[CTO]],"Otros") -> Otros | O8: =IF(PL[[#This Row],[STATUS IUP]]="CERRADO","CERRADO",IF(ISNUMBER(SEARCH("validacion de enel",PL[[#This Row],[SUPPLIER NOTES]])),"PTE Validar Enel","ABIERTO")) -> CERRADO | P8: =IF(PL[[#This Row],[ESTADO]]="CERRADO","Cerrados IUP",IF(PL[[#This Row],[ESTADO]]="PTE Validar Enel","Pendiente cierre ENEL",IF(ISNUMBER(SEARCH("suministro",PL[[#This Row],[SUPPLIER NOTES]])),"Suministros",IF(PL[[#This Row],[SC]]="SOCIAL","Social",IF(ISNUMBER(SEARCH("monolito",PL[[#This Row],[DESCRIPTION]])),"Monolitos","Varios"))))) -> Cerrados IUP | Q8: =IF(ISNA(MATCH(PL[[#This Row],[ITEM ID]],Externos!$A:$A,0)),"",IF(PL[[#This Row],[DETECTOR_ROLE]]="Sustainability Manager","SOCIAL",IF(INDEX(Externos!$D:$D,MATCH(PL[[#This Row],[ITEM ID]],Externos!$A:$A,0))="TRINA",IF(PL[[#This Row],[DETECTOR_ROLE]]="O&M","Trina O&M",IF(PL[[#This Row],[DETECTOR_ROLE]]="Commissioning Manager","Trina Commissioning","Trina Electric")),"O&M")))
A9: PHL-38985 | B9: Cables | C9: CAJAS | D9: CAJAS | E9: Caja de Empalme Sectioning Pit Cto 09 Suc 21 | F9: Retoque de pintura en tapas metalicas | G9: Civil Specialist | J9: CL | K9: CERRADO | M9: 46137 | N9: =IF(ISNUMBER(PL[[#This Row],[CTO]]),"CTO "&PL[[#This Row],[CTO]],"Otros") -> Otros | O9: =IF(PL[[#This Row],[STATUS IUP]]="CERRADO","CERRADO",IF(ISNUMBER(SEARCH("validacion de enel",PL[[#This Row],[SUPPLIER NOTES]])),"PTE Validar Enel","ABIERTO")) -> CERRADO | P9: =IF(PL[[#This Row],[ESTADO]]="CERRADO","Cerrados IUP",IF(PL[[#This Row],[ESTADO]]="PTE Validar Enel","Pendiente cierre ENEL",IF(ISNUMBER(SEARCH("suministro",PL[[#This Row],[SUPPLIER NOTES]])),"Suministros",IF(PL[[#This Row],[SC]]="SOCIAL","Social",IF(ISNUMBER(SEARCH("monolito",PL[[#This Row],[DESCRIPTION]])),"Monolitos","Varios"))))) -> Cerrados IUP | Q9: =IF(ISNA(MATCH(PL[[#This Row],[ITEM ID]],Externos!$A:$A,0)),"",IF(PL[[#This Row],[DETECTOR_ROLE]]="Sustainability Manager","SOCIAL",IF(INDEX(Externos!$D:$D,MATCH(PL[[#This Row],[ITEM ID]],Externos!$A:$A,0))="TRINA",IF(PL[[#This Row],[DETECTOR_ROLE]]="O&M","Trina O&M",IF(PL[[#This Row],[DETECTOR_ROLE]]="Commissioning Manager","Trina Commissioning","Trina Electric")),"O&M")))
A10: PHL-38988 | B10: Fiber optic | C10: CAJAS | D10: CAJAS | E10: Caja de Fusión FO Ctos (5-9) OC 9 | F10: Tapado de huecos de ingreso a caja. (Poliuretano) | G10: Electrical Specialist | J10: CL | K10: CERRADO | L10: 46293 | M10: 46137 | N10: =IF(ISNUMBER(PL[[#This Row],[CTO]]),"CTO "&PL[[#This Row],[CTO]],"Otros") -> Otros | O10: =IF(PL[[#This Row],[STATUS IUP]]="CERRADO","CERRADO",IF(ISNUMBER(SEARCH("validacion de enel",PL[[#This Row],[SUPPLIER NOTES]])),"PTE Validar Enel","ABIERTO")) -> CERRADO | P10: =IF(PL[[#This Row],[ESTADO]]="CERRADO","Cerrados IUP",IF(PL[[#This Row],[ESTADO]]="PTE Validar Enel","Pendiente cierre ENEL",IF(ISNUMBER(SEARCH("suministro",PL[[#This Row],[SUPPLIER NOTES]])),"Suministros",IF(PL[[#This Row],[SC]]="SOCIAL","Social",IF(ISNUMBER(SEARCH("monolito",PL[[#This Row],[DESCRIPTION]])),"Monolitos","Varios"))))) -> Cerrados IUP | Q10: =IF(ISNA(MATCH(PL[[#This Row],[ITEM ID]],Externos!$A:$A,0)),"",IF(PL[[#This Row],[DETECTOR_ROLE]]="Sustainability Manager","SOCIAL",IF(INDEX(Externos!$D:$D,MATCH(PL[[#This Row],[ITEM ID]],Externos!$A:$A,0))="TRINA",IF(PL[[#This Row],[DETECTOR_ROLE]]="O&M","Trina O&M",IF(PL[[#This Row],[DETECTOR_ROLE]]="Commissioning Manager","Trina Commissioning","Trina Electric")),"O&M")))
A11: PHL-38989 | B11: Fiber optic | C11: CAJAS | D11: CAJAS | E11: Caja de Fusión FO Ctos (5-9) OC 10 | F11: Ubicación final de caja | G11: Electrical Specialist | J11: CL | K11: CERRADO | L11: 46293 | M11: 46137 | N11: =IF(ISNUMBER(PL[[#This Row],[CTO]]),"CTO "&PL[[#This Row],[CTO]],"Otros") -> Otros | O11: =IF(PL[[#This Row],[STATUS IUP]]="CERRADO","CERRADO",IF(ISNUMBER(SEARCH("validacion de enel",PL[[#This Row],[SUPPLIER NOTES]])),"PTE Validar Enel","ABIERTO")) -> CERRADO | P11: =IF(PL[[#This Row],[ESTADO]]="CERRADO","Cerrados IUP",IF(PL[[#This Row],[ESTADO]]="PTE Validar Enel","Pendiente cierre ENEL",IF(ISNUMBER(SEARCH("suministro",PL[[#This Row],[SUPPLIER NOTES]])),"Suministros",IF(PL[[#This Row],[SC]]="SOCIAL","Social",IF(ISNUMBER(SEARCH("monolito",PL[[#This Row],[DESCRIPTION]])),"Monolitos","Varios"))))) -> Cerrados IUP | Q11: =IF(ISNA(MATCH(PL[[#This Row],[ITEM ID]],Externos!$A:$A,0)),"",IF(PL[[#This Row],[DETECTOR_ROLE]]="Sustainability Manager","SOCIAL",IF(INDEX(Externos!$D:$D,MATCH(PL[[#This Row],[ITEM ID]],Externos!$A:$A,0))="TRINA",IF(PL[[#This Row],[DETECTOR_ROLE]]="O&M","Trina O&M",IF(PL[[#This Row],[DETECTOR_ROLE]]="Commissioning Manager","Trina Commissioning","Trina Electric")),"O&M")))
A12: PHL-39059 | B12: Cables | C12: CAJAS | D12: CAJAS | E12: Caja de empalme continua a la ITS24 | F12: Limpieza de cables MT | G12: Electrical Specialist | J12: CL | K12: CERRADO | N12: =IF(ISNUMBER(PL[[#This Row],[CTO]]),"CTO "&PL[[#This Row],[CTO]],"Otros") -> Otros | O12: =IF(PL[[#This Row],[STATUS IUP]]="CERRADO","CERRADO",IF(ISNUMBER(SEARCH("validacion de enel",PL[[#This Row],[SUPPLIER NOTES]])),"PTE Validar Enel","ABIERTO")) -> CERRADO | P12: =IF(PL[[#This Row],[ESTADO]]="CERRADO","Cerrados IUP",IF(PL[[#This Row],[ESTADO]]="PTE Validar Enel","Pendiente cierre ENEL",IF(ISNUMBER(SEARCH("suministro",PL[[#This Row],[SUPPLIER NOTES]])),"Suministros",IF(PL[[#This Row],[SC]]="SOCIAL","Social",IF(ISNUMBER(SEARCH("monolito",PL[[#This Row],[DESCRIPTION]])),"Monolitos","Varios"))))) -> Cerrados IUP | Q12: =IF(ISNA(MATCH(PL[[#This Row],[ITEM ID]],Externos!$A:$A,0)),"",IF(PL[[#This Row],[DETECTOR_ROLE]]="Sustainability Manager","SOCIAL",IF(INDEX(Externos!$D:$D,MATCH(PL[[#This Row],[ITEM ID]],Externos!$A:$A,0))="TRINA",IF(PL[[#This Row],[DETECTOR_ROLE]]="O&M","Trina O&M",IF(PL[[#This Row],[DETECTOR_ROLE]]="Commissioning Manager","Trina Commissioning","Trina Electric")),"O&M")))
A13: PHL-39061 | B13: Cables | C13: CAJAS | D13: CAJAS | E13: Caja de empalme continua a la ITS24 | F13: Aterrizar tapas de cajas | G13: Electrical Specialist | J13: CL | K13: CERRADO | N13: =IF(ISNUMBER(PL[[#This Row],[CTO]]),"CTO "&PL[[#This Row],[CTO]],"Otros") -> Otros | O13: =IF(PL[[#This Row],[STATUS IUP]]="CERRADO","CERRADO",IF(ISNUMBER(SEARCH("validacion de enel",PL[[#This Row],[SUPPLIER NOTES]])),"PTE Validar Enel","ABIERTO")) -> CERRADO | P13: =IF(PL[[#This Row],[ESTADO]]="CERRADO","Cerrados IUP",IF(PL[[#This Row],[ESTADO]]="PTE Validar Enel","Pendiente cierre ENEL",IF(ISNUMBER(SEARCH("suministro",PL[[#This Row],[SUPPLIER NOTES]])),"Suministros",IF(PL[[#This Row],[SC]]="SOCIAL","Social",IF(ISNUMBER(SEARCH("monolito",PL[[#This Row],[DESCRIPTION]])),"Monolitos","Varios"))))) -> Cerrados IUP | Q13: =IF(ISNA(MATCH(PL[[#This Row],[ITEM ID]],Externos!$A:$A,0)),"",IF(PL[[#This Row],[DETECTOR_ROLE]]="Sustainability Manager","SOCIAL",IF(INDEX(Externos!$D:$D,MATCH(PL[[#This Row],[ITEM ID]],Externos!$A:$A,0))="TRINA",IF(PL[[#This Row],[DETECTOR_ROLE]]="O&M","Trina O&M",IF(PL[[#This Row],[DETECTOR_ROLE]]="Commissioning Manager","Trina Commissioning","Trina Electric")),"O&M")))
A14: PHL-39063 | B14: Cables | C14: CAJAS | D14: CAJAS | E14: Caja de empalme continua a la ITS24 | F14: Reconformacion de terreno alrededor de la caja | G14: Civil Specialist | J14: CL | K14: CERRADO | N14: =IF(ISNUMBER(PL[[#This Row],[CTO]]),"CTO "&PL[[#This Row],[CTO]],"Otros") -> Otros | O14: =IF(PL[[#This Row],[STATUS IUP]]="CERRADO","CERRADO",IF(ISNUMBER(SEARCH("validacion de enel",PL[[#This Row],[SUPPLIER NOTES]])),"PTE Validar Enel","ABIERTO")) -> CERRADO | P14: =IF(PL[[#This Row],[ESTADO]]="CERRADO","Cerrados IUP",IF(PL[[#This Row],[ESTADO]]="PTE Validar Enel","Pendiente cierre ENEL",IF(ISNUMBER(SEARCH("suministro",PL[[#This Row],[SUPPLIER NOTES]])),"Suministros",IF(PL[[#This Row],[SC]]="SOCIAL","Social",IF(ISNUMBER(SEARCH("monolito",PL[[#This Row],[DESCRIPTION]])),"Monolitos","Varios"))))) -> Cerrados IUP | Q14: =IF(ISNA(MATCH(PL[[#This Row],[ITEM ID]],Externos!$A:$A,0)),"",IF(PL[[#This Row],[DETECTOR_ROLE]]="Sustainability Manager","SOCIAL",IF(INDEX(Externos!$D:$D,MATCH(PL[[#This Row],[ITEM ID]],Externos!$A:$A,0))="TRINA",IF(PL[[#This Row],[DETECTOR_ROLE]]="O&M","Trina O&M",IF(PL[[#This Row],[DETECTOR_ROLE]]="Commissioning Manager","Trina Commissioning","Trina Electric")),"O&M")))
A15: PHL-39064 | B15: Cables | C15: CAJAS | D15: CAJAS | E15: Caja de empalme continua a la ITS24 | F15: Instalacion de tag y señalizacion RETIE | G15: Project HSE&Q support | J15: CL | K15: CERRADO | N15: =IF(ISNUMBER(PL[[#This Row],[CTO]]),"CTO "&PL[[#This Row],[CTO]],"Otros") -> Otros | O15: =IF(PL[[#This Row],[STATUS IUP]]="CERRADO","CERRADO",IF(ISNUMBER(SEARCH("validacion de enel",PL[[#This Row],[SUPPLIER NOTES]])),"PTE Validar Enel","ABIERTO")) -> CERRADO | P15: =IF(PL[[#This Row],[ESTADO]]="CERRADO","Cerrados IUP",IF(PL[[#This Row],[ESTADO]]="PTE Validar Enel","Pendiente cierre ENEL",IF(ISNUMBER(SEARCH("suministro",PL[[#This Row],[SUPPLIER NOTES]])),"Suministros",IF(PL[[#This Row],[SC]]="SOCIAL","Social",IF(ISNUMBER(SEARCH("monolito",PL[[#This Row],[DESCRIPTION]])),"Monolitos","Varios"))))) -> Cerrados IUP | Q15: =IF(ISNA(MATCH(PL[[#This Row],[ITEM ID]],Externos!$A:$A,0)),"",IF(PL[[#This Row],[DETECTOR_ROLE]]="Sustainability Manager","SOCIAL",IF(INDEX(Externos!$D:$D,MATCH(PL[[#This Row],[ITEM ID]],Externos!$A:$A,0))="TRINA",IF(PL[[#This Row],[DETECTOR_ROLE]]="O&M","Trina O&M",IF(PL[[#This Row],[DETECTOR_ROLE]]="Commissioning Manager","Trina Commissioning","Trina Electric")),"O&M")))
A16: PHL-39083 | B16: Cables | C16: CAJAS | D16: CAJAS | E16: caja de paso de la OC5 costado Sur de los CTOS 8-9-10 : | F16: Limpieza de cables MT | G16: Electrical Specialist | J16: CL | K16: CERRADO | N16: =IF(ISNUMBER(PL[[#This Row],[CTO]]),"CTO "&PL[[#This Row],[CTO]],"Otros") -> Otros | O16: =IF(PL[[#This Row],[STATUS IUP]]="CERRADO","CERRADO",IF(ISNUMBER(SEARCH("validacion de enel",PL[[#This Row],[SUPPLIER NOTES]])),"PTE Validar Enel","ABIERTO")) -> CERRADO | P16: =IF(PL[[#This Row],[ESTADO]]="CERRADO","Cerrados IUP",IF(PL[[#This Row],[ESTADO]]="PTE Validar Enel","Pendiente cierre ENEL",IF(ISNUMBER(SEARCH("suministro",PL[[#This Row],[SUPPLIER NOTES]])),"Suministros",IF(PL[[#This Row],[SC]]="SOCIAL","Social",IF(ISNUMBER(SEARCH("monolito",PL[[#This Row],[DESCRIPTION]])),"Monolitos","Varios"))))) -> Cerrados IUP | Q16: =IF(ISNA(MATCH(PL[[#This Row],[ITEM ID]],Externos!$A:$A,0)),"",IF(PL[[#This Row],[DETECTOR_ROLE]]="Sustainability Manager","SOCIAL",IF(INDEX(Externos!$D:$D,MATCH(PL[[#This Row],[ITEM ID]],Externos!$A:$A,0))="TRINA",IF(PL[[#This Row],[DETECTOR_ROLE]]="O&M","Trina O&M",IF(PL[[#This Row],[DETECTOR_ROLE]]="Commissioning Manager","Trina Commissioning","Trina Electric")),"O&M")))
A17: PHL-39085 | B17: Cables | C17: CAJAS | D17: CAJAS | E17: caja de paso de la OC5 costado Sur de los CTOS 8-9-10 : | F17: Aterrizar tapas de cajas | G17: Electrical Specialist | J17: CL | K17: CERRADO | N17: =IF(ISNUMBER(PL[[#This Row],[CTO]]),"CTO "&PL[[#This Row],[CTO]],"Otros") -> Otros | O17: =IF(PL[[#This Row],[STATUS IUP]]="CERRADO","CERRADO",IF(ISNUMBER(SEARCH("validacion de enel",PL[[#This Row],[SUPPLIER NOTES]])),"PTE Validar Enel","ABIERTO")) -> CERRADO | P17: =IF(PL[[#This Row],[ESTADO]]="CERRADO","Cerrados IUP",IF(PL[[#This Row],[ESTADO]]="PTE Validar Enel","Pendiente cierre ENEL",IF(ISNUMBER(SEARCH("suministro",PL[[#This Row],[SUPPLIER NOTES]])),"Suministros",IF(PL[[#This Row],[SC]]="SOCIAL","Social",IF(ISNUMBER(SEARCH("monolito",PL[[#This Row],[DESCRIPTION]])),"Monolitos","Varios"))))) -> Cerrados IUP | Q17: =IF(ISNA(MATCH(PL[[#This Row],[ITEM ID]],Externos!$A:$A,0)),"",IF(PL[[#This Row],[DETECTOR_ROLE]]="Sustainability Manager","SOCIAL",IF(INDEX(Externos!$D:$D,MATCH(PL[[#This Row],[ITEM ID]],Externos!$A:$A,0))="TRINA",IF(PL[[#This Row],[DETECTOR_ROLE]]="O&M","Trina O&M",IF(PL[[#This Row],[DETECTOR_ROLE]]="Commissioning Manager","Trina Commissioning","Trina Electric")),"O&M")))
A18: PHL-39801 | B18: LV/MV Cabin Others | C18: CAJAS | D18: CAJAS | E18: CTO10_MT_145 | F18: Caja de Empalme Sectioning Pit Cto 10 Lewis 6-7 | Instalación TAG | G18: Site Manager | H18: Pendiente validacion de enel | J18: CL | K18: CERRADO | L18: 46303 | N18: =IF(ISNUMBER(PL[[#This Row],[CTO]]),"CTO "&PL[[#This Row],[CTO]],"Otros") -> Otros | O18: =IF(PL[[#This Row],[STATUS IUP]]="CERRADO","CERRADO",IF(ISNUMBER(SEARCH("validacion de enel",PL[[#This Row],[SUPPLIER NOTES]])),"PTE Validar Enel","ABIERTO")) -> CERRADO | P18: =IF(PL[[#This Row],[ESTADO]]="CERRADO","Cerrados IUP",IF(PL[[#This Row],[ESTADO]]="PTE Validar Enel","Pendiente cierre ENEL",IF(ISNUMBER(SEARCH("suministro",PL[[#This Row],[SUPPLIER NOTES]])),"Suministros",IF(PL[[#This Row],[SC]]="SOCIAL","Social",IF(ISNUMBER(SEARCH("monolito",PL[[#This Row],[DESCRIPTION]])),"Monolitos","Varios"))))) -> Cerrados IUP | Q18: =IF(ISNA(MATCH(PL[[#This Row],[ITEM ID]],Externos!$A:$A,0)),"",IF(PL[[#This Row],[DETECTOR_ROLE]]="Sustainability Manager","SOCIAL",IF(INDEX(Externos!$D:$D,MATCH(PL[[#This Row],[ITEM ID]],Externos!$A:$A,0))="TRINA",IF(PL[[#This Row],[DETECTOR_ROLE]]="O&M","Trina O&M",IF(PL[[#This Row],[DETECTOR_ROLE]]="Commissioning Manager","Trina Commissioning","Trina Electric")),"O&M")))
A19: PHL-39087 | B19: Cables | C19: CAJAS | D19: CAJAS | E19: caja de paso de la OC5 costado Sur de los CTOS 8-9-10 : | F19: Reconformacion de terreno alrededor de la caja | G19: Civil Specialist | J19: CL | K19: CERRADO | N19: =IF(ISNUMBER(PL[[#This Row],[CTO]]),"CTO "&PL[[#This Row],[CTO]],"Otros") -> Otros | O19: =IF(PL[[#This Row],[STATUS IUP]]="CERRADO","CERRADO",IF(ISNUMBER(SEARCH("validacion de enel",PL[[#This Row],[SUPPLIER NOTES]])),"PTE Validar Enel","ABIERTO")) -> CERRADO | P19: =IF(PL[[#This Row],[ESTADO]]="CERRADO","Cerrados IUP",IF(PL[[#This Row],[ESTADO]]="PTE Validar Enel","Pendiente cierre ENEL",IF(ISNUMBER(SEARCH("suministro",PL[[#This Row],[SUPPLIER NOTES]])),"Suministros",IF(PL[[#This Row],[SC]]="SOCIAL","Social",IF(ISNUMBER(SEARCH("monolito",PL[[#This Row],[DESCRIPTION]])),"Monolitos","Varios"))))) -> Cerrados IUP | Q19: =IF(ISNA(MATCH(PL[[#This Row],[ITEM ID]],Externos!$A:$A,0)),"",IF(PL[[#This Row],[DETECTOR_ROLE]]="Sustainability Manager","SOCIAL",IF(INDEX(Externos!$D:$D,MATCH(PL[[#This Row],[ITEM ID]],Externos!$A:$A,0))="TRINA",IF(PL[[#This Row],[DETECTOR_ROLE]]="O&M","Trina O&M",IF(PL[[#This Row],[DETECTOR_ROLE]]="Commissioning Manager","Trina Commissioning","Trina Electric")),"O&M")))
A20: PHL-39089 | B20: Cables | C20: CAJAS | D20: CAJAS | E20: caja de paso de la OC5 costado Sur de los CTOS 8-9-10 : | F20: Retoque de pintura en tapas metalicas | G20: Civil Specialist | I20: Farid consolido en cierre | J20: CL | K20: CERRADO | L20: 46288 | N20: =IF(ISNUMBER(PL[[#This Row],[CTO]]),"CTO "&PL[[#This Row],[CTO]],"Otros") -> Otros | O20: =IF(PL[[#This Row],[STATUS IUP]]="CERRADO","CERRADO",IF(ISNUMBER(SEARCH("validacion de enel",PL[[#This Row],[SUPPLIER NOTES]])),"PTE Validar Enel","ABIERTO")) -> CERRADO | P20: =IF(PL[[#This Row],[ESTADO]]="CERRADO","Cerrados IUP",IF(PL[[#This Row],[ESTADO]]="PTE Validar Enel","Pendiente cierre ENEL",IF(ISNUMBER(SEARCH("suministro",PL[[#This Row],[SUPPLIER NOTES]])),"Suministros",IF(PL[[#This Row],[SC]]="SOCIAL","Social",IF(ISNUMBER(SEARCH("monolito",PL[[#This Row],[DESCRIPTION]])),"Monolitos","Varios"))))) -> Cerrados IUP | Q20: =IF(ISNA(MATCH(PL[[#This Row],[ITEM ID]],Externos!$A:$A,0)),"",IF(PL[[#This Row],[DETECTOR_ROLE]]="Sustainability Manager","SOCIAL",IF(INDEX(Externos!$D:$D,MATCH(PL[[#This Row],[ITEM ID]],Externos!$A:$A,0))="TRINA",IF(PL[[#This Row],[DETECTOR_ROLE]]="O&M","Trina O&M",IF(PL[[#This Row],[DETECTOR_ROLE]]="Commissioning Manager","Trina Commissioning","Trina Electric")),"O&M")))
A21: PHL-39091 | B21: Cables | C21: CAJAS | D21: CAJAS | E21: Caja de paso del costado norte de la OC5 de los CTOS 8-9-11 | F21: Limpieza de cables MT | G21: Electrical Specialist | J21: CL | K21: CERRADO | N21: =IF(ISNUMBER(PL[[#This Row],[CTO]]),"CTO "&PL[[#This Row],[CTO]],"Otros") -> Otros | O21: =IF(PL[[#This Row],[STATUS IUP]]="CERRADO","CERRADO",IF(ISNUMBER(SEARCH("validacion de enel",PL[[#This Row],[SUPPLIER NOTES]])),"PTE Validar Enel","ABIERTO")) -> CERRADO | P21: =IF(PL[[#This Row],[ESTADO]]="CERRADO","Cerrados IUP",IF(PL[[#This Row],[ESTADO]]="PTE Validar Enel","Pendiente cierre ENEL",IF(ISNUMBER(SEARCH("suministro",PL[[#This Row],[SUPPLIER NOTES]])),"Suministros",IF(PL[[#This Row],[SC]]="SOCIAL","Social",IF(ISNUMBER(SEARCH("monolito",PL[[#This Row],[DESCRIPTION]])),"Monolitos","Varios"))))) -> Cerrados IUP | Q21: =IF(ISNA(MATCH(PL[[#This Row],[ITEM ID]],Externos!$A:$A,0)),"",IF(PL[[#This Row],[DETECTOR_ROLE]]="Sustainability Manager","SOCIAL",IF(INDEX(Externos!$D:$D,MATCH(PL[[#This Row],[ITEM ID]],Externos!$A:$A,0))="TRINA",IF(PL[[#This Row],[DETECTOR_ROLE]]="O&M","Trina O&M",IF(PL[[#This Row],[DETECTOR_ROLE]]="Commissioning Manager","Trina Commissioning","Trina Electric")),"O&M")))
A22: PHL-39093 | B22: Cables | C22: CAJAS | D22: CAJAS | E22: Caja de paso del costado norte de la OC5 de los CTOS 8-9-13 | F22: Aterrizar tapas de cajas | G22: Electrical Specialist | J22: CL | K22: CERRADO | N22: =IF(ISNUMBER(PL[[#This Row],[CTO]]),"CTO "&PL[[#This Row],[CTO]],"Otros") -> Otros | O22: =IF(PL[[#This Row],[STATUS IUP]]="CERRADO","CERRADO",IF(ISNUMBER(SEARCH("validacion de enel",PL[[#This Row],[SUPPLIER NOTES]])),"PTE Validar Enel","ABIERTO")) -> CERRADO | P22: =IF(PL[[#This Row],[ESTADO]]="CERRADO","Cerrados IUP",IF(PL[[#This Row],[ESTADO]]="PTE Validar Enel","Pendiente cierre ENEL",IF(ISNUMBER(SEARCH("suministro",PL[[#This Row],[SUPPLIER NOTES]])),"Suministros",IF(PL[[#This Row],[SC]]="SOCIAL","Social",IF(ISNUMBER(SEARCH("monolito",PL[[#This Row],[DESCRIPTION]])),"Monolitos","Varios"))))) -> Cerrados IUP | Q22: =IF(ISNA(MATCH(PL[[#This Row],[ITEM ID]],Externos!$A:$A,0)),"",IF(PL[[#This Row],[DETECTOR_ROLE]]="Sustainability Manager","SOCIAL",IF(INDEX(Externos!$D:$D,MATCH(PL[[#This Row],[ITEM ID]],Externos!$A:$A,0))="TRINA",IF(PL[[#This Row],[DETECTOR_ROLE]]="O&M","Trina O&M",IF(PL[[#This Row],[DETECTOR_ROLE]]="Commissioning Manager","Trina Commissioning","Trina Electric")),"O&M")))
A23: PHL-39094 | B23: Cables | C23: CAJAS | D23: CAJAS | E23: Caja de paso del costado norte de la OC5 de los CTOS 8-9-14 | F23: Reconformacion de terreno alrededor de la caja | G23: Civil Specialist | J23: CL | K23: CERRADO | N23: =IF(ISNUMBER(PL[[#This Row],[CTO]]),"CTO "&PL[[#This Row],[CTO]],"Otros") -> Otros | O23: =IF(PL[[#This Row],[STATUS IUP]]="CERRADO","CERRADO",IF(ISNUMBER(SEARCH("validacion de enel",PL[[#This Row],[SUPPLIER NOTES]])),"PTE Validar Enel","ABIERTO")) -> CERRADO | P23: =IF(PL[[#This Row],[ESTADO]]="CERRADO","Cerrados IUP",IF(PL[[#This Row],[ESTADO]]="PTE Validar Enel","Pendiente cierre ENEL",IF(ISNUMBER(SEARCH("suministro",PL[[#This Row],[SUPPLIER NOTES]])),"Suministros",IF(PL[[#This Row],[SC]]="SOCIAL","Social",IF(ISNUMBER(SEARCH("monolito",PL[[#This Row],[DESCRIPTION]])),"Monolitos","Varios"))))) -> Cerrados IUP | Q23: =IF(ISNA(MATCH(PL[[#This Row],[ITEM ID]],Externos!$A:$A,0)),"",IF(PL[[#This Row],[DETECTOR_ROLE]]="Sustainability Manager","SOCIAL",IF(INDEX(Externos!$D:$D,MATCH(PL[[#This Row],[ITEM ID]],Externos!$A:$A,0))="TRINA",IF(PL[[#This Row],[DETECTOR_ROLE]]="O&M","Trina O&M",IF(PL[[#This Row],[DETECTOR_ROLE]]="Commissioning Manager","Trina Commissioning","Trina Electric")),"O&M")))
A24: PHL-39097 | B24: Cables | C24: CAJAS | D24: CAJAS | E24: Caja de Empalme Sectioning Pit Cto 09 Lewis 6-7 | F24: Sellado ductos material impermeabilizante | G24: Electrical Specialist | J24: CL | K24: CERRADO | N24: =IF(ISNUMBER(PL[[#This Row],[CTO]]),"CTO "&PL[[#This Row],[CTO]],"Otros") -> Otros | O24: =IF(PL[[#This Row],[STATUS IUP]]="CERRADO","CERRADO",IF(ISNUMBER(SEARCH("validacion de enel",PL[[#This Row],[SUPPLIER NOTES]])),"PTE Validar Enel","ABIERTO")) -> CERRADO | P24: =IF(PL[[#This Row],[ESTADO]]="CERRADO","Cerrados IUP",IF(PL[[#This Row],[ESTADO]]="PTE Validar Enel","Pendiente cierre ENEL",IF(ISNUMBER(SEARCH("suministro",PL[[#This Row],[SUPPLIER NOTES]])),"Suministros",IF(PL[[#This Row],[SC]]="SOCIAL","Social",IF(ISNUMBER(SEARCH("monolito",PL[[#This Row],[DESCRIPTION]])),"Monolitos","Varios"))))) -> Cerrados IUP | Q24: =IF(ISNA(MATCH(PL[[#This Row],[ITEM ID]],Externos!$A:$A,0)),"",IF(PL[[#This Row],[DETECTOR_ROLE]]="Sustainability Manager","SOCIAL",IF(INDEX(Externos!$D:$D,MATCH(PL[[#This Row],[ITEM ID]],Externos!$A:$A,0))="TRINA",IF(PL[[#This Row],[DETECTOR_ROLE]]="O&M","Trina O&M",IF(PL[[#This Row],[DETECTOR_ROLE]]="Commissioning Manager","Trina Commissioning","Trina Electric")),"O&M")))
A25: PHL-39098 | B25: Cables | C25: CAJAS | D25: CAJAS | E25: Caja de Empalme Sectioning Pit Cto 09 Lewis 6-8 | F25: Limpieza de cables MT | G25: Electrical Specialist | J25: CL | K25: CERRADO | N25: =IF(ISNUMBER(PL[[#This Row],[CTO]]),"CTO "&PL[[#This Row],[CTO]],"Otros") -> Otros | O25: =IF(PL[[#This Row],[STATUS IUP]]="CERRADO","CERRADO",IF(ISNUMBER(SEARCH("validacion de enel",PL[[#This Row],[SUPPLIER NOTES]])),"PTE Validar Enel","ABIERTO")) -> CERRADO | P25: =IF(PL[[#This Row],[ESTADO]]="CERRADO","Cerrados IUP",IF(PL[[#This Row],[ESTADO]]="PTE Validar Enel","Pendiente cierre ENEL",IF(ISNUMBER(SEARCH("suministro",PL[[#This Row],[SUPPLIER NOTES]])),"Suministros",IF(PL[[#This Row],[SC]]="SOCIAL","Social",IF(ISNUMBER(SEARCH("monolito",PL[[#This Row],[DESCRIPTION]])),"Monolitos","Varios"))))) -> Cerrados IUP | Q25: =IF(ISNA(MATCH(PL[[#This Row],[ITEM ID]],Externos!$A:$A,0)),"",IF(PL[[#This Row],[DETECTOR_ROLE]]="Sustainability Manager","SOCIAL",IF(INDEX(Externos!$D:$D,MATCH(PL[[#This Row],[ITEM ID]],Externos!$A:$A,0))="TRINA",IF(PL[[#This Row],[DETECTOR_ROLE]]="O&M","Trina O&M",IF(PL[[#This Row],[DETECTOR_ROLE]]="Commissioning Manager","Trina Commissioning","Trina Electric")),"O&M")))
A26: PHL-39100 | B26: Cables | C26: CAJAS | D26: CAJAS | E26: Caja de Empalme Sectioning Pit Cto 09 Lewis 6-10 | F26: Aterrizar tapas de cajas | G26: Electrical Specialist | J26: CL | K26: CERRADO | N26: =IF(ISNUMBER(PL[[#This Row],[CTO]]),"CTO "&PL[[#This Row],[CTO]],"Otros") -> Otros | O26: =IF(PL[[#This Row],[STATUS IUP]]="CERRADO","CERRADO",IF(ISNUMBER(SEARCH("validacion de enel",PL[[#This Row],[SUPPLIER NOTES]])),"PTE Validar Enel","ABIERTO")) -> CERRADO | P26: =IF(PL[[#This Row],[ESTADO]]="CERRADO","Cerrados IUP",IF(PL[[#This Row],[ESTADO]]="PTE Validar Enel","Pendiente cierre ENEL",IF(ISNUMBER(SEARCH("suministro",PL[[#This Row],[SUPPLIER NOTES]])),"Suministros",IF(PL[[#This Row],[SC]]="SOCIAL","Social",IF(ISNUMBER(SEARCH("monolito",PL[[#This Row],[DESCRIPTION]])),"Monolitos","Varios"))))) -> Cerrados IUP | Q26: =IF(ISNA(MATCH(PL[[#This Row],[ITEM ID]],Externos!$A:$A,0)),"",IF(PL[[#This Row],[DETECTOR_ROLE]]="Sustainability Manager","SOCIAL",IF(INDEX(Externos!$D:$D,MATCH(PL[[#This Row],[ITEM ID]],Externos!$A:$A,0))="TRINA",IF(PL[[#This Row],[DETECTOR_ROLE]]="O&M","Trina O&M",IF(PL[[#This Row],[DETECTOR_ROLE]]="Commissioning Manager","Trina Commissioning","Trina Electric")),"O&M")))
A27: PHL-39101 | B27: Cables | C27: CAJAS | D27: CAJAS | E27: Caja de Empalme Sectioning Pit Cto 09 Lewis 6-11 | F27: Reconformacion de terreno alrededor de la caja | G27: Civil Specialist | J27: CL | K27: CERRADO | N27: =IF(ISNUMBER(PL[[#This Row],[CTO]]),"CTO "&PL[[#This Row],[CTO]],"Otros") -> Otros | O27: =IF(PL[[#This Row],[STATUS IUP]]="CERRADO","CERRADO",IF(ISNUMBER(SEARCH("validacion de enel",PL[[#This Row],[SUPPLIER NOTES]])),"PTE Validar Enel","ABIERTO")) -> CERRADO | P27: =IF(PL[[#This Row],[ESTADO]]="CERRADO","Cerrados IUP",IF(PL[[#This Row],[ESTADO]]="PTE Validar Enel","Pendiente cierre ENEL",IF(ISNUMBER(SEARCH("suministro",PL[[#This Row],[SUPPLIER NOTES]])),"Suministros",IF(PL[[#This Row],[SC]]="SOCIAL","Social",IF(ISNUMBER(SEARCH("monolito",PL[[#This Row],[DESCRIPTION]])),"Monolitos","Varios"))))) -> Cerrados IUP | Q27: =IF(ISNA(MATCH(PL[[#This Row],[ITEM ID]],Externos!$A:$A,0)),"",IF(PL[[#This Row],[DETECTOR_ROLE]]="Sustainability Manager","SOCIAL",IF(INDEX(Externos!$D:$D,MATCH(PL[[#This Row],[ITEM ID]],Externos!$A:$A,0))="TRINA",IF(PL[[#This Row],[DETECTOR_ROLE]]="O&M","Trina O&M",IF(PL[[#This Row],[DETECTOR_ROLE]]="Commissioning Manager","Trina Commissioning","Trina Electric")),"O&M")))
A28: PHL-39506 | B28: Trenches and Cable Way | C28: CAJAS | D28: CAJAS | E28: MT CTO10_ (123) -Cajas de paso OC1 costado norte y sur: | F28: Instalación TAG | G28: Electrical Specialist | J28: CL | K28: CERRADO | N28: =IF(ISNUMBER(PL[[#This Row],[CTO]]),"CTO "&PL[[#This Row],[CTO]],"Otros") -> Otros | O28: =IF(PL[[#This Row],[STATUS IUP]]="CERRADO","CERRADO",IF(ISNUMBER(SEARCH("validacion de enel",PL[[#This Row],[SUPPLIER NOTES]])),"PTE Validar Enel","ABIERTO")) -> CERRADO | P28: =IF(PL[[#This Row],[ESTADO]]="CERRADO","Cerrados IUP",IF(PL[[#This Row],[ESTADO]]="PTE Validar Enel","Pendiente cierre ENEL",IF(ISNUMBER(SEARCH("suministro",PL[[#This Row],[SUPPLIER NOTES]])),"Suministros",IF(PL[[#This Row],[SC]]="SOCIAL","Social",IF(ISNUMBER(SEARCH("monolito",PL[[#This Row],[DESCRIPTION]])),"Monolitos","Varios"))))) -> Cerrados IUP | Q28: =IF(ISNA(MATCH(PL[[#This Row],[ITEM ID]],Externos!$A:$A,0)),"",IF(PL[[#This Row],[DETECTOR_ROLE]]="Sustainability Manager","SOCIAL",IF(INDEX(Externos!$D:$D,MATCH(PL[[#This Row],[ITEM ID]],Externos!$A:$A,0))="TRINA",IF(PL[[#This Row],[DETECTOR_ROLE]]="O&M","Trina O&M",IF(PL[[#This Row],[DETECTOR_ROLE]]="Commissioning Manager","Trina Commissioning","Trina Electric")),"O&M")))
A29: PHL-39507 | B29: Trenches and Cable Way | C29: CAJAS | D29: CAJAS | E29: MT CTO10_ (126)Cajas de paso OC1 costado norte y sur: | F29: orden y aseo | G29: Environmental Discipline | J29: CL | K29: CERRADO | N29: =IF(ISNUMBER(PL[[#This Row],[CTO]]),"CTO "&PL[[#This Row],[CTO]],"Otros") -> Otros | O29: =IF(PL[[#This Row],[STATUS IUP]]="CERRADO","CERRADO",IF(ISNUMBER(SEARCH("validacion de enel",PL[[#This Row],[SUPPLIER NOTES]])),"PTE Validar Enel","ABIERTO")) -> CERRADO | P29: =IF(PL[[#This Row],[ESTADO]]="CERRADO","Cerrados IUP",IF(PL[[#This Row],[ESTADO]]="PTE Validar Enel","Pendiente cierre ENEL",IF(ISNUMBER(SEARCH("suministro",PL[[#This Row],[SUPPLIER NOTES]])),"Suministros",IF(PL[[#This Row],[SC]]="SOCIAL","Social",IF(ISNUMBER(SEARCH("monolito",PL[[#This Row],[DESCRIPTION]])),"Monolitos","Varios"))))) -> Cerrados IUP | Q29: =IF(ISNA(MATCH(PL[[#This Row],[ITEM ID]],Externos!$A:$A,0)),"",IF(PL[[#This Row],[DETECTOR_ROLE]]="Sustainability Manager","SOCIAL",IF(INDEX(Externos!$D:$D,MATCH(PL[[#This Row],[ITEM ID]],Externos!$A:$A,0))="TRINA",IF(PL[[#This Row],[DETECTOR_ROLE]]="O&M","Trina O&M",IF(PL[[#This Row],[DETECTOR_ROLE]]="Commissioning Manager","Trina Commissioning","Trina Electric")),"O&M")))
A30: PHL-39508 | B30: Trenches and Cable Way | C30: CAJAS | D30: CAJAS | E30: MT CTO10_(127)-Cajas de paso OC1 costado norte y sur: | F30: conformación de terreno | G30: Civil Specialist | J30: CL | K30: CERRADO | N30: =IF(ISNUMBER(PL[[#This Row],[CTO]]),"CTO "&PL[[#This Row],[CTO]],"Otros") -> Otros | O30: =IF(PL[[#This Row],[STATUS IUP]]="CERRADO","CERRADO",IF(ISNUMBER(SEARCH("validacion de enel",PL[[#This Row],[SUPPLIER NOTES]])),"PTE Validar Enel","ABIERTO")) -> CERRADO | P30: =IF(PL[[#This Row],[ESTADO]]="CERRADO","Cerrados IUP",IF(PL[[#This Row],[ESTADO]]="PTE Validar Enel","Pendiente cierre ENEL",IF(ISNUMBER(SEARCH("suministro",PL[[#This Row],[SUPPLIER NOTES]])),"Suministros",IF(PL[[#This Row],[SC]]="SOCIAL","Social",IF(ISNUMBER(SEARCH("monolito",PL[[#This Row],[DESCRIPTION]])),"Monolitos","Varios"))))) -> Cerrados IUP | Q30: =IF(ISNA(MATCH(PL[[#This Row],[ITEM ID]],Externos!$A:$A,0)),"",IF(PL[[#This Row],[DETECTOR_ROLE]]="Sustainability Manager","SOCIAL",IF(INDEX(Externos!$D:$D,MATCH(PL[[#This Row],[ITEM ID]],Externos!$A:$A,0))="TRINA",IF(PL[[#This Row],[DETECTOR_ROLE]]="O&M","Trina O&M",IF(PL[[#This Row],[DETECTOR_ROLE]]="Commissioning Manager","Trina Commissioning","Trina Electric")),"O&M")))
A31: PHL-39510 | B31: Trenches and Cable Way | C31: CAJAS | D31: CAJAS | E31: MT CTO10_(131)Caja empalme Promigas 5 costado sur: | F31: conformación de terreno | G31: Civil Specialist | J31: CL | K31: CERRADO | N31: =IF(ISNUMBER(PL[[#This Row],[CTO]]),"CTO "&PL[[#This Row],[CTO]],"Otros") -> Otros | O31: =IF(PL[[#This Row],[STATUS IUP]]="CERRADO","CERRADO",IF(ISNUMBER(SEARCH("validacion de enel",PL[[#This Row],[SUPPLIER NOTES]])),"PTE Validar Enel","ABIERTO")) -> CERRADO | P31: =IF(PL[[#This Row],[ESTADO]]="CERRADO","Cerrados IUP",IF(PL[[#This Row],[ESTADO]]="PTE Validar Enel","Pendiente cierre ENEL",IF(ISNUMBER(SEARCH("suministro",PL[[#This Row],[SUPPLIER NOTES]])),"Suministros",IF(PL[[#This Row],[SC]]="SOCIAL","Social",IF(ISNUMBER(SEARCH("monolito",PL[[#This Row],[DESCRIPTION]])),"Monolitos","Varios"))))) -> Cerrados IUP | Q31: =IF(ISNA(MATCH(PL[[#This Row],[ITEM ID]],Externos!$A:$A,0)),"",IF(PL[[#This Row],[DETECTOR_ROLE]]="Sustainability Manager","SOCIAL",IF(INDEX(Externos!$D:$D,MATCH(PL[[#This Row],[ITEM ID]],Externos!$A:$A,0))="TRINA",IF(PL[[#This Row],[DETECTOR_ROLE]]="O&M","Trina O&M",IF(PL[[#This Row],[DETECTOR_ROLE]]="Commissioning Manager","Trina Commissioning","Trina Electric")),"O&M")))
A32: PHL-39511 | B32: Trenches and Cable Way | C32: CAJAS | D32: CAJAS | E32: MT CTO10_(134)Caja de paso Promigas 5 costado norte | F32: orden y aseo | G32: Environmental Discipline | J32: CL | K32: CERRADO | N32: =IF(ISNUMBER(PL[[#This Row],[CTO]]),"CTO "&PL[[#This Row],[CTO]],"Otros") -> Otros | O32: =IF(PL[[#This Row],[STATUS IUP]]="CERRADO","CERRADO",IF(ISNUMBER(SEARCH("validacion de enel",PL[[#This Row],[SUPPLIER NOTES]])),"PTE Validar Enel","ABIERTO")) -> CERRADO | P32: =IF(PL[[#This Row],[ESTADO]]="CERRADO","Cerrados IUP",IF(PL[[#This Row],[ESTADO]]="PTE Validar Enel","Pendiente cierre ENEL",IF(ISNUMBER(SEARCH("suministro",PL[[#This Row],[SUPPLIER NOTES]])),"Suministros",IF(PL[[#This Row],[SC]]="SOCIAL","Social",IF(ISNUMBER(SEARCH("monolito",PL[[#This Row],[DESCRIPTION]])),"Monolitos","Varios"))))) -> Cerrados IUP | Q32: =IF(ISNA(MATCH(PL[[#This Row],[ITEM ID]],Externos!$A:$A,0)),"",IF(PL[[#This Row],[DETECTOR_ROLE]]="Sustainability Manager","SOCIAL",IF(INDEX(Externos!$D:$D,MATCH(PL[[#This Row],[ITEM ID]],Externos!$A:$A,0))="TRINA",IF(PL[[#This Row],[DETECTOR_ROLE]]="O&M","Trina O&M",IF(PL[[#This Row],[DETECTOR_ROLE]]="Commissioning Manager","Trina Commissioning","Trina Electric")),"O&M")))
A33: PHL-39517 | B33: Trenches and Cable Way | C33: CAJAS | D33: CAJAS | E33: MT CTO10_(145)Caja de Empalme Sectioning Pit Cto 10 Lewis 6-7 | F33: Instalación TAG | G33: Electrical Specialist | J33: CL | K33: CERRADO | L33: 46293 | N33: =IF(ISNUMBER(PL[[#This Row],[CTO]]),"CTO "&PL[[#This Row],[CTO]],"Otros") -> Otros | O33: =IF(PL[[#This Row],[STATUS IUP]]="CERRADO","CERRADO",IF(ISNUMBER(SEARCH("validacion de enel",PL[[#This Row],[SUPPLIER NOTES]])),"PTE Validar Enel","ABIERTO")) -> CERRADO | P33: =IF(PL[[#This Row],[ESTADO]]="CERRADO","Cerrados IUP",IF(PL[[#This Row],[ESTADO]]="PTE Validar Enel","Pendiente cierre ENEL",IF(ISNUMBER(SEARCH("suministro",PL[[#This Row],[SUPPLIER NOTES]])),"Suministros",IF(PL[[#This Row],[SC]]="SOCIAL","Social",IF(ISNUMBER(SEARCH("monolito",PL[[#This Row],[DESCRIPTION]])),"Monolitos","Varios"))))) -> Cerrados IUP | Q33: =IF(ISNA(MATCH(PL[[#This Row],[ITEM ID]],Externos!$A:$A,0)),"",IF(PL[[#This Row],[DETECTOR_ROLE]]="Sustainability Manager","SOCIAL",IF(INDEX(Externos!$D:$D,MATCH(PL[[#This Row],[ITEM ID]],Externos!$A:$A,0))="TRINA",IF(PL[[#This Row],[DETECTOR_ROLE]]="O&M","Trina O&M",IF(PL[[#This Row],[DETECTOR_ROLE]]="Commissioning Manager","Trina Commissioning","Trina Electric")),"O&M")))
A34: PHL-39519 | B34: Trenches and Cable Way | C34: CAJAS | D34: CAJAS | E34: MT CTO10_(148)Caja de Empalme Sectioning Pit Cto 10 Lewis 6-7 | F34: Marcacion de tapas de caja de fibra | G34: Electrical Specialist | J34: CL | K34: CERRADO | N34: =IF(ISNUMBER(PL[[#This Row],[CTO]]),"CTO "&PL[[#This Row],[CTO]],"Otros") -> Otros | O34: =IF(PL[[#This Row],[STATUS IUP]]="CERRADO","CERRADO",IF(ISNUMBER(SEARCH("validacion de enel",PL[[#This Row],[SUPPLIER NOTES]])),"PTE Validar Enel","ABIERTO")) -> CERRADO | P34: =IF(PL[[#This Row],[ESTADO]]="CERRADO","Cerrados IUP",IF(PL[[#This Row],[ESTADO]]="PTE Validar Enel","Pendiente cierre ENEL",IF(ISNUMBER(SEARCH("suministro",PL[[#This Row],[SUPPLIER NOTES]])),"Suministros",IF(PL[[#This Row],[SC]]="SOCIAL","Social",IF(ISNUMBER(SEARCH("monolito",PL[[#This Row],[DESCRIPTION]])),"Monolitos","Varios"))))) -> Cerrados IUP | Q34: =IF(ISNA(MATCH(PL[[#This Row],[ITEM ID]],Externos!$A:$A,0)),"",IF(PL[[#This Row],[DETECTOR_ROLE]]="Sustainability Manager","SOCIAL",IF(INDEX(Externos!$D:$D,MATCH(PL[[#This Row],[ITEM ID]],Externos!$A:$A,0))="TRINA",IF(PL[[#This Row],[DETECTOR_ROLE]]="O&M","Trina O&M",IF(PL[[#This Row],[DETECTOR_ROLE]]="Commissioning Manager","Trina Commissioning","Trina Electric")),"O&M")))
A35: PHL-39520 | B35: Trenches and Cable Way | C35: CAJAS | D35: CAJAS | E35: MT CTO10_(149)Caja de Empalme Sectioning Pit Cto 10 Lewis 6-7 | F35: ⁠conformación de Terreno Cajas de Fusión FO | G35: Civil Specialist | J35: CL | K35: CERRADO | N35: =IF(ISNUMBER(PL[[#This Row],[CTO]]),"CTO "&PL[[#This Row],[CTO]],"Otros") -> Otros | O35: =IF(PL[[#This Row],[STATUS IUP]]="CERRADO","CERRADO",IF(ISNUMBER(SEARCH("validacion de enel",PL[[#This Row],[SUPPLIER NOTES]])),"PTE Validar Enel","ABIERTO")) -> CERRADO | P35: =IF(PL[[#This Row],[ESTADO]]="CERRADO","Cerrados IUP",IF(PL[[#This Row],[ESTADO]]="PTE Validar Enel","Pendiente cierre ENEL",IF(ISNUMBER(SEARCH("suministro",PL[[#This Row],[SUPPLIER NOTES]])),"Suministros",IF(PL[[#This Row],[SC]]="SOCIAL","Social",IF(ISNUMBER(SEARCH("monolito",PL[[#This Row],[DESCRIPTION]])),"Monolitos","Varios"))))) -> Cerrados IUP | Q35: =IF(ISNA(MATCH(PL[[#This Row],[ITEM ID]],Externos!$A:$A,0)),"",IF(PL[[#This Row],[DETECTOR_ROLE]]="Sustainability Manager","SOCIAL",IF(INDEX(Externos!$D:$D,MATCH(PL[[#This Row],[ITEM ID]],Externos!$A:$A,0))="TRINA",IF(PL[[#This Row],[DETECTOR_ROLE]]="O&M","Trina O&M",IF(PL[[#This Row],[DETECTOR_ROLE]]="Commissioning Manager","Trina Commissioning","Trina Electric")),"O&M")))
A36: PHL-39521 | B36: Trenches and Cable Way | C36: CAJAS | D36: CAJAS | E36: MT CTO_(150)Caja de Empalme Sectioning Pit Cto 10 Lewis 6-7 | F36: conformación de terreno Cajas de Empalme Sectioning Pit | G36: Civil Specialist | J36: CL | K36: CERRADO | N36: =IF(ISNUMBER(PL[[#This Row],[CTO]]),"CTO "&PL[[#This Row],[CTO]],"Otros") -> Otros | O36: =IF(PL[[#This Row],[STATUS IUP]]="CERRADO","CERRADO",IF(ISNUMBER(SEARCH("validacion de enel",PL[[#This Row],[SUPPLIER NOTES]])),"PTE Validar Enel","ABIERTO")) -> CERRADO | P36: =IF(PL[[#This Row],[ESTADO]]="CERRADO","Cerrados IUP",IF(PL[[#This Row],[ESTADO]]="PTE Validar Enel","Pendiente cierre ENEL",IF(ISNUMBER(SEARCH("suministro",PL[[#This Row],[SUPPLIER NOTES]])),"Suministros",IF(PL[[#This Row],[SC]]="SOCIAL","Social",IF(ISNUMBER(SEARCH("monolito",PL[[#This Row],[DESCRIPTION]])),"Monolitos","Varios"))))) -> Cerrados IUP | Q36: =IF(ISNA(MATCH(PL[[#This Row],[ITEM ID]],Externos!$A:$A,0)),"",IF(PL[[#This Row],[DETECTOR_ROLE]]="Sustainability Manager","SOCIAL",IF(INDEX(Externos!$D:$D,MATCH(PL[[#This Row],[ITEM ID]],Externos!$A:$A,0))="TRINA",IF(PL[[#This Row],[DETECTOR_ROLE]]="O&M","Trina O&M",IF(PL[[#This Row],[DETECTOR_ROLE]]="Commissioning Manager","Trina Commissioning","Trina Electric")),"O&M")))
A37: PHL-39522 | B37: Trenches and Cable Way | C37: CAJAS | D37: CAJAS | E37: MT CTO_(155)Caja de Empalme Sectioning Pit Cto 10 Lewis 6-7 -Norte | F37: Limpieza general | G37: Environmental Discipline | J37: CL | K37: CERRADO | N37: =IF(ISNUMBER(PL[[#This Row],[CTO]]),"CTO "&PL[[#This Row],[CTO]],"Otros") -> Otros | O37: =IF(PL[[#This Row],[STATUS IUP]]="CERRADO","CERRADO",IF(ISNUMBER(SEARCH("validacion de enel",PL[[#This Row],[SUPPLIER NOTES]])),"PTE Validar Enel","ABIERTO")) -> CERRADO | P37: =IF(PL[[#This Row],[ESTADO]]="CERRADO","Cerrados IUP",IF(PL[[#This Row],[ESTADO]]="PTE Validar Enel","Pendiente cierre ENEL",IF(ISNUMBER(SEARCH("suministro",PL[[#This Row],[SUPPLIER NOTES]])),"Suministros",IF(PL[[#This Row],[SC]]="SOCIAL","Social",IF(ISNUMBER(SEARCH("monolito",PL[[#This Row],[DESCRIPTION]])),"Monolitos","Varios"))))) -> Cerrados IUP | Q37: =IF(ISNA(MATCH(PL[[#This Row],[ITEM ID]],Externos!$A:$A,0)),"",IF(PL[[#This Row],[DETECTOR_ROLE]]="Sustainability Manager","SOCIAL",IF(INDEX(Externos!$D:$D,MATCH(PL[[#This Row],[ITEM ID]],Externos!$A:$A,0))="TRINA",IF(PL[[#This Row],[DETECTOR_ROLE]]="O&M","Trina O&M",IF(PL[[#This Row],[DETECTOR_ROLE]]="Commissioning Manager","Trina Commissioning","Trina Electric")),"O&M")))
A38: PHL-39523 | B38: Trenches and Cable Way | C38: CAJAS | D38: CAJAS | E38: MT CTO10_(156)Caja de Empalme Sectioning Pit Cto 10 Lewis 6-7 -Norte | F38: Adecuación del terreno | G38: Civil Specialist | J38: CL | K38: CERRADO | N38: =IF(ISNUMBER(PL[[#This Row],[CTO]]),"CTO "&PL[[#This Row],[CTO]],"Otros") -> Otros | O38: =IF(PL[[#This Row],[STATUS IUP]]="CERRADO","CERRADO",IF(ISNUMBER(SEARCH("validacion de enel",PL[[#This Row],[SUPPLIER NOTES]])),"PTE Validar Enel","ABIERTO")) -> CERRADO | P38: =IF(PL[[#This Row],[ESTADO]]="CERRADO","Cerrados IUP",IF(PL[[#This Row],[ESTADO]]="PTE Validar Enel","Pendiente cierre ENEL",IF(ISNUMBER(SEARCH("suministro",PL[[#This Row],[SUPPLIER NOTES]])),"Suministros",IF(PL[[#This Row],[SC]]="SOCIAL","Social",IF(ISNUMBER(SEARCH("monolito",PL[[#This Row],[DESCRIPTION]])),"Monolitos","Varios"))))) -> Cerrados IUP | Q38: =IF(ISNA(MATCH(PL[[#This Row],[ITEM ID]],Externos!$A:$A,0)),"",IF(PL[[#This Row],[DETECTOR_ROLE]]="Sustainability Manager","SOCIAL",IF(INDEX(Externos!$D:$D,MATCH(PL[[#This Row],[ITEM ID]],Externos!$A:$A,0))="TRINA",IF(PL[[#This Row],[DETECTOR_ROLE]]="O&M","Trina O&M",IF(PL[[#This Row],[DETECTOR_ROLE]]="Commissioning Manager","Trina Commissioning","Trina Electric")),"O&M")))
A39: PHL-39790 | B39: LV/MV Cabin Others | C39: CAJAS | D39: CAJAS | E39: CTO10_MT_123 | F39: Cajas de paso OC1 costado norte y sur: | Instalación TAG | G39: Site Manager | J39: CL | K39: CERRADO | N39: =IF(ISNUMBER(PL[[#This Row],[CTO]]),"CTO "&PL[[#This Row],[CTO]],"Otros") -> Otros | O39: =IF(PL[[#This Row],[STATUS IUP]]="CERRADO","CERRADO",IF(ISNUMBER(SEARCH("validacion de enel",PL[[#This Row],[SUPPLIER NOTES]])),"PTE Validar Enel","ABIERTO")) -> CERRADO | P39: =IF(PL[[#This Row],[ESTADO]]="CERRADO","Cerrados IUP",IF(PL[[#This Row],[ESTADO]]="PTE Validar Enel","Pendiente cierre ENEL",IF(ISNUMBER(SEARCH("suministro",PL[[#This Row],[SUPPLIER NOTES]])),"Suministros",IF(PL[[#This Row],[SC]]="SOCIAL","Social",IF(ISNUMBER(SEARCH("monolito",PL[[#This Row],[DESCRIPTION]])),"Monolitos","Varios"))))) -> Cerrados IUP | Q39: =IF(ISNA(MATCH(PL[[#This Row],[ITEM ID]],Externos!$A:$A,0)),"",IF(PL[[#This Row],[DETECTOR_ROLE]]="Sustainability Manager","SOCIAL",IF(INDEX(Externos!$D:$D,MATCH(PL[[#This Row],[ITEM ID]],Externos!$A:$A,0))="TRINA",IF(PL[[#This Row],[DETECTOR_ROLE]]="O&M","Trina O&M",IF(PL[[#This Row],[DETECTOR_ROLE]]="Commissioning Manager","Trina Commissioning","Trina Electric")),"O&M")))
A40: PHL-39791 | B40: LV/MV Cabin Others | C40: CAJAS | D40: CAJAS | E40: CTO10_MT_126 | F40: Cajas de paso OC1 costado norte y sur: | orden y aseo | G40: Site Manager | J40: CL | K40: CERRADO | N40: =IF(ISNUMBER(PL[[#This Row],[CTO]]),"CTO "&PL[[#This Row],[CTO]],"Otros") -> Otros | O40: =IF(PL[[#This Row],[STATUS IUP]]="CERRADO","CERRADO",IF(ISNUMBER(SEARCH("validacion de enel",PL[[#This Row],[SUPPLIER NOTES]])),"PTE Validar Enel","ABIERTO")) -> CERRADO | P40: =IF(PL[[#This Row],[ESTADO]]="CERRADO","Cerrados IUP",IF(PL[[#This Row],[ESTADO]]="PTE Validar Enel","Pendiente cierre ENEL",IF(ISNUMBER(SEARCH("suministro",PL[[#This Row],[SUPPLIER NOTES]])),"Suministros",IF(PL[[#This Row],[SC]]="SOCIAL","Social",IF(ISNUMBER(SEARCH("monolito",PL[[#This Row],[DESCRIPTION]])),"Monolitos","Varios"))))) -> Cerrados IUP | Q40: =IF(ISNA(MATCH(PL[[#This Row],[ITEM ID]],Externos!$A:$A,0)),"",IF(PL[[#This Row],[DETECTOR_ROLE]]="Sustainability Manager","SOCIAL",IF(INDEX(Externos!$D:$D,MATCH(PL[[#This Row],[ITEM ID]],Externos!$A:$A,0))="TRINA",IF(PL[[#This Row],[DETECTOR_ROLE]]="O&M","Trina O&M",IF(PL[[#This Row],[DETECTOR_ROLE]]="Commissioning Manager","Trina Commissioning","Trina Electric")),"O&M")))
...

Sheet OTROS
A1: ITEM ID | B1: PART | C1: SC | D1: FUNCTIONAL_PART | E1: DESCRIPTION | F1: DETECTOR_ROLE | G1: SUPPLIER NOTES | H1: CLOSING NOTES | I1: STATUS ELECNOR | J1: STATUS IUP | K1: CLOSING DATE ENEL | L1: CLOSING DATE - ELECNOR
A2: PHL-40712 | B2: Others | C2: SOCIAL | E2: Reuniones de socialización de cierre de la etapa constructiva en Usiacurí y Sabanalarga, con autoridades locales, comunidades del AI, propietarios vecinos y propietarios de los predios donde se realiza la intervención.| en cumplimiento de: ANEXO W1 - OBLIGACIONES DE LICENCIA AMBIENTAL SOSTENIBILIDAD | F2: Sustainability Manager | I2: OP | J2: ABIERTO
A3: PHL-40713 | B3: Others | C3: SOCIAL | E3: Visita guiada de cierre con actores clave (autoridades y comunidad) para validar el área intervenida y confirmar el 100% de condiciones finales del proyecto.| en cumplimiento de: ANEXO W1 - OBLIGACIONES DE LICENCIA AMBIENTAL SOSTENIBILIDAD | F3: Sustainability Manager | I3: OP | J3: ABIERTO
A4: PHL-40714 | B4: Others | C4: SOCIAL | E4: Cierre del 100% de las PQRSDF (Actualmente se tienen 6 en total: 5 en gestión y 1 abierta). Sin embargo, se deben atender todas las que se generen en la posteridad hasta el cierre total del proyecto. | en cumplimiento de: ANEXO W1 - OBLIGACIONES DE LICENCIA AMBIENTAL SOSTENIBILIDAD | F4: Sustainability Manager | I4: OP | J4: ABIERTO
A5: PHL-40715 | B5: Others | C5: SOCIAL | E5: Ejecución de 1 recorrido final de verificación de infraestructura vial con autoridades y comunidad de Isabel López, levantando actas y garantizando la ejecución del 100% de las reparaciones atribuibles al proyecto en la vía Isabel López - Usiacurí. | en cumplimiento de: ANEXO W1 - OBLIGACIONES DE LICENCIA AMBIENTAL SOSTENIBILIDAD | F5: Sustainability Manager | I5: OP | J5: ABIERTO
A6: PHL-40716 | B6: Others | C6: SOCIAL | E6: Cierre de 217 actas de vecindad (207 viviendas aferentes a vía Isabel López - Usiacurí, 5 correspondientes a predios vecinos y 5 relacionadas con infraestructura comunitaria) asegurando documentación completa, legibilidad y entrega de copias a los titulares.| en cumplimiento de: ANEXO W1 - OBLIGACIONES DE LICENCIA AMBIENTAL SOSTENIBILIDAD | F6: Sustainability Manager | I6: OP | J6: ABIERTO
A7: PHL-40717 | B7: Others | C7: SOCIAL | E7: Gestionar el cierre del punto de atención a la comunidad, incluyendo la entrega de soportes finales de operación y la obtención del paz y salvo correspondiente (100%) que certifique la finalización adecuada del servicio.| en cumplimiento de: ANEXO W1 - OBLIGACIONES DE LICENCIA AMBIENTAL SOSTENIBILIDAD | F7: Sustainability Manager | I7: OP | J7: ABIERTO
A8: PHL-40718 | B8: Others | C8: SOCIAL | E8: Informe final de la implementación del PMT y cierre con autoridades competentes (esto incluye el retiro del 100% de los elementos de señalización y control de tránsito implementados durante el proyecto).| en cumplimiento de: ANEXO W1 - OBLIGACIONES DE LICENCIA AMBIENTAL SOSTENIBILIDAD | F8: Sustainability Manager | I8: OP | J8: ABIERTO
A9: PHL-40719 | B9: Others | C9: SOCIAL | E9: Entrega de 2 tanques de almacenamiento de agua a comunidad priorizada en el marco de la estrategia de sitio de construcción sostenible.| en cumplimiento de: ANEXO H y BoQ SOSTENIBILIDAD | F9: Sustainability Manager | I9: OP | J9: ABIERTO
A10: PHL-40720 | B10: Others | C10: SOCIAL | E10: Entrega 2 desfibriladores externos automáticos (DEA) y realizar la capacitación básica en primeros auxilios a los beneficiarios. | en cumplimiento de: ANEXO H y BoQ SOSTENIBILIDAD | F10: Sustainability Manager | I10: OP | J10: ABIERTO
A11: PHL-40721 | B11: Others | C11: SOCIAL | E11: Soportes de ejecución de las actividades de Sitio de Construcción Sostenible establecidas en BoQ y en propuesta aprobada. | en cumplimiento de: ANEXO H y BoQ SOSTENIBILIDAD | F11: Sustainability Manager | I11: OP | J11: ABIERTO
A12: PHL-40722 | B12: Others | C12: SOCIAL | E12: Entregar 1 dossier social final que incluya el 100% de soportes correspondientes. | en cumplimiento de: ANEXO H SOSTENIBILIDAD | F12: Sustainability Manager | I12: OP | J12: ABIERTO
A13: PHL-40723 | B13: Others | C13: SOCIAL | E13: Realizar reunión final de Comité de Empleo y Seguimiento, comunicando formalmente la finalización del 100% de las actividades constructivas y el cierre de la vinculación laboral asociada al proyecto.| en cumplimiento de: ANEXO H SOSTENIBILIDAD | F13: Sustainability Manager | I13: OP | J13: ABIERTO
... A16: PHL-40726 | B16: Others | C16: SOCIAL | E16: Paz y salvo por concepto de adquisición de todo tipo de servicios que se dieron en ocasión de su presencia y la de sus contratistas en el sector.| en cumplimiento de: ANEXO H SOSTENIBILIDAD | F16: Sustainability Manager | I16: OP | J16: ABIERTO
A17: PHL-40178 | B17: Others | C17: TRINA | E17: SI.33.01 Se evidencia vandalizado. Fueron cortadas todas las string de llegada al inversor. | F17: O&M | G17: se confirma cierre | H17: se confirma cierre | I17: CL | J17: CERRADO | K17: 2026-07-23 | L17: 2026-07-23
A18: PHL-40179 | B18: Others | C18: TRINA | E18: SI.33.02 vandalizado todas las strings de llegada al inversor están cortadas. | F18: O&M | G18: se confrima cierre | H18: se cofnirma cierre | I18: CL | J18: CERRADO | K18: 2026-07-23 | L18: 2026-07-23
A19: PHL-41023 | B19: Others | C19: TRINA | E19: evaluacion, aprobacion y entrega de Curvas I-V en 15 subcampos del parque zona norte | F19: Commissioning Manager | I19: OP | J19: ABIERTO
A20: PHL-41024 | B20: Others | C20: TRINA | E20: realizar y entregar informes de Termografías con dron en 15 subcampos del norte | F20: Commissioning Manager | I20: OP | J20: ABIERTO
A21: PHL-41025 | B21: Others | C21: TRINA | E21: Instalación Terminal Latiguillo SPT Antena NCU. Suc 32: | F21: Electrical Discipline | I21: OP | J21: ABIERTO
A22: PHL-41026 | B22: Others | C22: TRINA | E22: Conexionado, Toque y Testigo Terminal Latiguillo SPT Antena NCU. Suc 32: | F22: Electrical Discipline | I22: OP | J22: ABIERTO
A23: PHL-41029 | B23: Others | C23: TRINA | E23: - ⁠Torque y Testigo Conexión Latiguillo SPT Lado BT CT 30. | F23: Electrical Discipline | I23: OP | J23: ABIERTO
A24: PHL-41030 | B24: Others | C24: TRINA | E24: - Instalación Platina de Sujeción CT 30. | F24: Electrical Discipline | I24: OP | J24: ABIERTO
A25: PHL-41031 | B25: Others | C25: TRINA | E25: - ⁠Aplicación de Espuma Poliuretano y Multiseal Afloramiento Banco de Ductos Potencia y FO CT30. | F25: Electrical Discipline | I25: OP | J25: ABIERTO
A26: PHL-41032 | B26: Others | C26: TRINA | E26: PL Suc 29. - Instalación Platina de Sujeción CT e instalación Tornillos Platina de Sujeción CT 29. | F26: Electrical Discipline | I26: CL | J26: CERRADO | K26: 46293
A27: PHL-40189 | B27: PV Tracker system | C27: TRINA | E27: : SI 34.06 traker 082 string 09 panel averiado | F27: O&M | I27: OP | J27: ABIERTO
A28: PHL-40190 | B28: PV Tracker system | C28: TRINA | E28: SI 34.08 traker 080. string 12 panel averiado | F28: O&M | I28: OP | J28: ABIERTO
A29: PHL-40727 | B29: PV Tracker system | C29: TRINA | E29: pte correccion/instalacion comm: Antena Rota en SC: 20 ncu: 15 MA0520-MQR017 | F29: Commissioning Manager | I29: OP | J29: ABIERTO
A30: PHL-40728 | B30: PV Tracker system | C30: TRINA | E30: pte correccion/instalacion comm: Antena Rota en SC: 20 ncu: 15 MA0520-MQR049 | F30: Commissioning Manager | I30: OP | J30: ABIERTO
A31: PHL-40729 | B31: PV Tracker system | C31: TRINA | E31: pte correccion/instalacion comm: Obstaculos (Impide movimiento) en SC: 20 ncu: 15 MA0520-MQR058 | F31: Commissioning Manager | I31: OP | J31: ABIERTO
A32: PHL-40730 | B32: PV Tracker system | C32: TRINA | E32: pte correccion/instalacion comm: Obstaculos (Impide movimiento) en SC: 21 ncu: 17 MA0521-MQR001 | F32: Commissioning Manager | I32: OP | J32: ABIERTO
A33: PHL-40731 | B33: PV Tracker system | C33: TRINA | E33: pte correccion/instalacion comm: Obstaculos (Impide movimiento) en SC: 21 ncu: 17 MA0521-MQR002 | F33: Commissioning Manager | I33: OP | J33: ABIERTO
A34: PHL-40732 | B34: PV Tracker system | C34: TRINA | E34: pte correccion/instalacion comm: String erroneo en SC: 21 ncu: 17 MA0521-MQR063 | F34: Commissioning Manager | I34: OP | J34: ABIERTO
A35: PHL-40733 | B35: PV Tracker system | C35: TRINA | E35: pte correccion/instalacion comm: TCU Maestra en SC: 21 ncu: 17 MA0521-MQR070 | F35: Commissioning Manager | I35: OP | J35: ABIERTO
A36: PHL-40734 | B36: PV Tracker system | C36: TRINA | E36: pte correccion/instalacion comm: TCU Master primero revisar String erroneo en SC: 21 ncu: 17 MA0521-MQR081 | F36: Commissioning Manager | I36: OP | J36: ABIERTO
A37: PHL-40735 | B37: PV Tracker system | C37: TRINA | E37: pte correccion/instalacion comm: Actuador Eslava 8 en SC: 21 ncu: 17 MA0521-MQR083 | F37: Commissioning Manager | I37: OP | J37: ABIERTO
A38: PHL-40736 | B38: PV Tracker system | C38: TRINA | E38: pte correccion/instalacion comm: Obstaculos (Impide movimiento) en SC: 21 ncu: 17 MA0521-MQR114 | F38: Commissioning Manager | I38: OP | J38: ABIERTO
... A157: PHL-40869 | B157: LV/MV Transformation Cabin | C157: CAJAS | E157: Pendiente para todas las cabinas la señalización de advertencia de la energía incidente, arco eléctrico, categoría del epp a utilizar y distancia de seguridad. (general) en sc | F157: Site Manager | I157: OP | J157: ABIERTO
A158: PHL-39096 | B158: Cables | C158: CAJAS | D158: Caja de paso del costado norte de la OC5 de los CTOS 8-9-16 | E158: Retoque de pintura en tapas metalicas | F158: Civil Specialist | I158: OP | J158: ABIERTO
A159: PHL-39065 | B159: Cables | C159: CAJAS | D159: Caja de empalme continua a la ITS24 | E159: Retoque de pintura en tapas metalicas | F159: Civil Specialist | I159: OP | J159: ABIERTO
A160: PHL-39062 | B160: Cables | C160: CAJAS | D160: Caja de empalme continua a la ITS24 | E160: Instalacion de monolitos | F160: Electrical Specialist | I160: OP | J160: ABIERTO
...

Sheet CTO 5
A1: ITEM ID | B1: PART | C1: SC | D1: FUNCTIONAL_PART | E1: DESCRIPTION | F1: DETECTOR_ROLE | G1: SUPPLIER NOTES | H1: CLOSING NOTES | I1: STATUS ELECNOR | J1: STATUS IUP | K1: CLOSING DATE ENEL | L1: CLOSING DATE - ELECNOR
A2: PHL-39066 | B2: Cables | C2: SC20 | D2: Caja de paso de MT de los circuitos 8-9-10 del SC20 (cruce PR5) | E2: Sellado ductos material impermeabilizante | F2: Electrical Specialist | I2: CERRADO | J2: PTE Validar Enel | L2: 46254
A3: PHL-39067 | B3: Cables | C3: SC20 | D3: Caja de paso de MT de los circuitos 8-9-10 del SC20 (cruce PR5) | E3: Limpieza de cables MT | F3: Electrical Specialist | I3: CERRADO | J3: PTE Validar Enel | L3: 46254
A4: PHL-39068 | B4: Cables | C4: SC20 | D4: Caja de paso de MT de los circuitos 8-9-10 del SC20 (cruce PR5) | E4: Aterrizar tapas de cajas | F4: Electrical Specialist | I4: CERRADO | J4: PTE Validar Enel | L4: 46254
A5: PHL-39069 | B5: Cables | C5: SC20 | D5: Caja de paso de MT de los circuitos 8-9-10 del SC20 (cruce PR5) | E5: Instalacion de monolitos | F5: Electrical Specialist | I5: ABIERTO | J5: ABIERTO | L5: 46254
A6: PHL-39070 | B6: Cables | C6: SC20 | D6: Caja de paso de MT de los circuitos 8-9-10 del SC20 (cruce PR5) | E6: Reconformacion de terreno alrededor de la caja | F6: Electrical Specialist | I6: CERRADO | J6: PTE Validar Enel | L6: 46254
A7: PHL-39071 | B7: Cables | C7: SC20 | D7: Caja de paso de MT de los circuitos 8-9-10 del SC20 (cruce PR5) | E7: Instalacion de tag y señalizacion RETIE | F7: Civil Specialist | I7: CERRADO | J7: PTE Validar Enel | L7: 46254
A8: PHL-39072 | B8: Cables | C8: SC20 | D8: Caja de paso de MT de los circuitos 8-9-10 del SC20 (cruce PR5) | E8: Retoque de pintura en tapas metalicas | F8: Safety and Environmental coordinator | I8: CERRADO | J8: PTE Validar Enel | L8: 46254
